Workbook

Sheet Start_Here
B1: MGMT-6124 Questionnaire Assignment: Analysis Workbook
B2: Topic: Generative AI at Work and in School. This workbook is empty until you paste in your REAL survey responses. Nothing here is sample data.
B4: How to use it
B5: 1. Build the Google Form (create_form.gs does it for you), share it, and let responses come in.
B6: 2. In the form: Responses > Link to Sheets (or the three-dot menu > Download responses (.csv)).
B7: 3. Open the export. Copy ALL cells, including the header row, and paste into Responses!A1. Column ORDER must stay the same (Timestamp, then Q1 to Q14, with Q6 as three columns). Header wording does not matter to the formulas.
B8: 4. Check the Live check box below. Then read Summary (one block + chart per question), then the XTab sheets (differences by group).
B9: 5. Look at the 'Largest differences' table at the top of each XTab sheet. Those are your candidate 'interesting findings'. Then confirm them by looking at the group sizes (small groups are flagged red).
B10: 6. Copy charts/tables into your report. Write the interpretation in the yellow cells on Summary as you go.
B12: Settings (blue text on yellow = you can edit)
B13: Minimum respondents required (assignment) | C13: 30 | D13: The assignment requires at least 30 respondents.
B14: People you invited (for overall response rate) | D14: Add up everyone you sent the link to. Leave blank until you know.
B15: Small-group warning below n = | C15: 5 | D15: Groups smaller than this are flagged red on the XTab sheets. Treat their percentages as anecdotal.
B16: 'Notable difference' gap (percentage points) | C16: 0.2 | D16: Gaps between groups at or above this are highlighted amber on the XTab sheets.
B18: Live check (formulas, do not overwrite)
B19: Total responses received | C19: =COUNTA(Responses!$A$2:$A$1000) -> 0
B20: Minimum met? | C20: =IF(C19>=Start_Here!$C$13,"Yes: " & C19 & " responses","Not yet: need " & (Start_Here!$C$13-C19) & " more") -> Not yet: need 30 more
B21: Overall response rate (responses / people invited) | C21: =IF(N(Start_Here!$C$14)>0,C19/Start_Here!$C$14,"Enter people invited above") -> Enter people invited above
B22: Respondents who use AI tools (shown Q4 to Q7) | C22: =COUNTIFS(Responses!$D$2:$D$1000,"<>Never",Responses!$D$2:$D$1000,"<>") -> 0
B23: Share of respondents who use AI tools | C23: =IF(C19=0,"",C22/C19)
B25: Branching: who is asked what
B26: Anyone who answers 'Never' to Q3 skips Q4 to Q7 (they do not use AI tools, so the questions do not apply). Those blanks are NOT missing data. On Summary, 'Base' for Q4 to Q7 is therefore the number of AI users, and the response rate is answered / base.
B28: Format example of ONE pasted row (not counted anywhere)
B29: Column (Responses sheet) | C29: Example value | D29: Note
B30: Timestamp | C30: 2026-10-20 14:32:07 | D30: Added automatically by Google Forms.
B31: Q1 Age group | C31: 25 to 34 | D31: Text must match the option wording on the form.
B32: Q2 Main activity | C32: Employed only (full-time or part-time) | D32: Text must match the option wording on the form.
B33: Q3 Frequency of use | C33: A few times a week | D33: Text must match the option wording on the form.
B34: Q4 Tasks AI is used for | C34: Writing or editing, Research or summarizing | D34: Checkbox answers arrive as ONE cell with answers separated by commas. The workbook searches inside the cell.
B35: Q5 Hours saved per week | C35: 1 to 3 hours | D35: Text must match the option wording on the form.
B36: Q6 [AI tools help me complete tasks fa...] | C36: Agree | D36: Exactly one of: Strongly disagree, Disagree, Neutral, Agree, Strongly agree
B37: Q6 [AI tools improve the quality of my...] | C37: Agree | D37: Exactly one of: Strongly disagree, Disagree, Neutral, Agree, Strongly agree
B38: Q6 [I always check AI-generated output...] | C38: Agree | D38: Exactly one of: Strongly disagree, Disagree, Neutral, Agree, Strongly agree
B39: Q7 Confidence using AI | C39: 4 | D39: Scale answers are numbers 1 to 5.
B40: Q8 Guidance received | C40: Written policy or guidelines only | D40: Text must match the option wording on the form.
... B46: Q14 Open comment | C46: (any free text, or blank) | D46: Optional. Blank is normal.
B48: Making a real PivotTable (your professor asked for pivot tables / cross tabs in Excel)
B49: The XTab sheets already hold formula-based cross tabulations. To also show a PivotTable (recommended, it is what the course video teaches), do this at least once for your report:
B50: a) Click any cell in the Responses table. Insert > PivotTable > New Worksheet.
B51: b) Drag 'Q1. Which age group are you in?' to Rows, 'Q3. How often do you use...' to Columns, and Q3 again to Values (Count).
...

Sheet Responses
A1: Timestamp | B1: Q1. Which age group are you in? | C1: Q2. Which best describes what you do right now? | D1: Q3. How often do you use generative AI tools (for example ChatGPT, Copilot, Gemini or Claude) for work or study? | E1: Q4. Which tasks do you use AI tools for? Select all that apply. | F1: Q5. On average, about how much time per week do AI tools save you? | G1: Q6. How much do you agree with each statement about your own use of AI tools? [AI tools help me complete tasks faster.] | H1: Q6. How much do you agree with each statement about your own use of AI tools? [AI tools improve the quality of my work.] | I1: Q6. How much do you agree with each statement about your own use of AI tools? [I always check AI-generated output before I use it.] | J1: Q7. How confident are you in your ability to use AI tools effectively? | K1: Q8. Which best describes the guidance you have received about using AI tools from your employer or school? | L1: Q9. Which best describes your employer's or school's current approach to AI tools? | M1: Q10. What are the biggest barriers to using AI tools (more) in your work or study? Select up to 3. | N1: Q11. "AI will reduce job opportunities in my field over the next 5 years." How much do you agree? | O1: Q12. If your employer or school invested in ONE of these, which would help you most? | P1: Q13. Over the next 12 months, do you expect your use of AI tools to change? | Q1: Q14. In a sentence or two, what is the single biggest benefit or risk of AI tools for your work or study? (optional)

Sheet Summary
A1: Question-by-question summary
A2: Counts, % and charts update automatically from the Responses sheet. 'Response rate' = answered / base (those shown the question).
A3: Total responses: | B3: =Start_Here!$C$19 -> 0
A5: Q1. Which age group are you in?
A6: Type: Multiple choice (single answer) | Base: all respondents
A7: Response option | B7: Count | C7: % of answered
A8: 18 to 24 | B8: =COUNTIF(Responses!$B$2:$B$1000,A8) -> 0 | C8: =IF($B$12=0,"",B8/$B$12)
A9: 25 to 34 | B9: =COUNTIF(Responses!$B$2:$B$1000,A9) -> 0 | C9: =IF($B$12=0,"",B9/$B$12)
A10: 35 to 44 | B10: =COUNTIF(Responses!$B$2:$B$1000,A10) -> 0 | C10: =IF($B$12=0,"",B10/$B$12)
A11: 45 or older | B11: =COUNTIF(Responses!$B$2:$B$1000,A11) -> 0 | C11: =IF($B$12=0,"",B11/$B$12)
A12: Answered (n) | B12: =COUNTA(Responses!$B$2:$B$1000) -> 0
A13: Base (shown the question) | B13: =Start_Here!$C$19 -> 0
A14: Response rate | B14: =IF(B13=0,"",B12/B13)
A15: Unmatched answers (should be 0; if not, edit label to match the form) | B15: =B12-SUM(B8:B11) -> 0
A23: Interpretation (draft your 2 to 3 sentences here):
A25: Q2. Which best describes what you do right now?
A26: Type: Multiple choice (single answer) | Base: all respondents
A27: Response option | B27: Count | C27: % of answered
A28: Student only | B28: =COUNTIF(Responses!$C$2:$C$1000,A28) -> 0 | C28: =IF($B$32=0,"",B28/$B$32)
A29: Employed only (full-time or part-time) | B29: =COUNTIF(Responses!$C$2:$C$1000,A29) -> 0 | C29: =IF($B$32=0,"",B29/$B$32)
A30: Both student and employed | B30: =COUNTIF(Responses!$C$2:$C$1000,A30) -> 0 | C30: =IF($B$32=0,"",B30/$B$32)
A31: Neither at the moment | B31: =COUNTIF(Responses!$C$2:$C$1000,A31) -> 0 | C31: =IF($B$32=0,"",B31/$B$32)
A32: Answered (n) | B32: =COUNTA(Responses!$C$2:$C$1000) -> 0
A33: Base (shown the question) | B33: =Start_Here!$C$19 -> 0
A34: Response rate | B34: =IF(B33=0,"",B32/B33)
A35: Unmatched answers (should be 0; if not, edit label to match the form) | B35: =B32-SUM(B28:B31) -> 0
A43: Interpretation (draft your 2 to 3 sentences here):
A45: Q3. How often do you use generative AI tools (for example ChatGPT, Copilot, Gemini or Claude) for work or study?
A46: Type: Multiple choice (single answer) | Base: all respondents
A47: Response option | B47: Count | C47: % of answered
A48: Never | B48: =COUNTIF(Responses!$D$2:$D$1000,A48) -> 0 | C48: =IF($B$53=0,"",B48/$B$53)
A49: Less than once a month | B49: =COUNTIF(Responses!$D$2:$D$1000,A49) -> 0 | C49: =IF($B$53=0,"",B49/$B$53)
A50: A few times a month | B50: =COUNTIF(Responses!$D$2:$D$1000,A50) -> 0 | C50: =IF($B$53=0,"",B50/$B$53)
A51: A few times a week | B51: =COUNTIF(Responses!$D$2:$D$1000,A51) -> 0 | C51: =IF($B$53=0,"",B51/$B$53)
A52: Daily | B52: =COUNTIF(Responses!$D$2:$D$1000,A52) -> 0 | C52: =IF($B$53=0,"",B52/$B$53)
A53: Answered (n) | B53: =COUNTA(Responses!$D$2:$D$1000) -> 0
A54: Base (shown the question) | B54: =Start_Here!$C$19 -> 0
A55: Response rate | B55: =IF(B54=0,"",B53/B54)
A56: Unmatched answers (should be 0; if not, edit label to match the form) | B56: =B53-SUM(B48:B52) -> 0
A63: Interpretation (draft your 2 to 3 sentences here):
...

Sheet XTab_Age
A1: Cross-tabs by age group (Q1)
A2: Do answers differ by age? Percentages are within each age group. Counts on the left, column % on the right.
A4: Group | B4: n | C4: % of sample | D4: Flag
A5: 18 to 24 | B5: =COUNTIF(Responses!$B$2:$B$1000,A5) -> 0 | C5: =IF(Start_Here!$C$19=0,"",B5/Start_Here!$C$19) | D5: =IF(B5<Start_Here!$C$15,"small n","") -> small n
A6: 25 to 34 | B6: =COUNTIF(Responses!$B$2:$B$1000,A6) -> 0 | C6: =IF(Start_Here!$C$19=0,"",B6/Start_Here!$C$19) | D6: =IF(B6<Start_Here!$C$15,"small n","") -> small n
A7: 35 to 44 | B7: =COUNTIF(Responses!$B$2:$B$1000,A7) -> 0 | C7: =IF(Start_Here!$C$19=0,"",B7/Start_Here!$C$19) | D7: =IF(B7<Start_Here!$C$15,"small n","") -> small n
A8: 45 or older | B8: =COUNTIF(Responses!$B$2:$B$1000,A8) -> 0 | C8: =IF(Start_Here!$C$19=0,"",B8/Start_Here!$C$19) | D8: =IF(B8<Start_Here!$C$15,"small n","") -> small n
A10: Largest differences between groups (top 5, in percentage points)
A11: Row (question / option) | B11: Qn | C11: Gap | D11: Highest group | H11: Lowest group | L11: (row ref)
A12: =IF(L12="","",INDEX($A$21:$A$147,L12)) | B12: =IF(L12="","",INDEX($N$21:$N$147,L12)) | C12: =IF(L12="","",INDEX($M$21:$M$147,L12)) | D12: =IF(L12="","",INDEX($P$21:$P$147,L12)) | H12: =IF(L12="","",INDEX($Q$21:$Q$147,L12)) | L12: =IFERROR(MATCH(LARGE($O$21:$O$147,1),$O$21:$O$147,0),"")
A13: =IF(L13="","",INDEX($A$21:$A$147,L13)) | B13: =IF(L13="","",INDEX($N$21:$N$147,L13)) | C13: =IF(L13="","",INDEX($M$21:$M$147,L13)) | D13: =IF(L13="","",INDEX($P$21:$P$147,L13)) | H13: =IF(L13="","",INDEX($Q$21:$Q$147,L13)) | L13: =IFERROR(MATCH(LARGE($O$21:$O$147,2),$O$21:$O$147,0),"")
A14: =IF(L14="","",INDEX($A$21:$A$147,L14)) | B14: =IF(L14="","",INDEX($N$21:$N$147,L14)) | C14: =IF(L14="","",INDEX($M$21:$M$147,L14)) | D14: =IF(L14="","",INDEX($P$21:$P$147,L14)) | H14: =IF(L14="","",INDEX($Q$21:$Q$147,L14)) | L14: =IFERROR(MATCH(LARGE($O$21:$O$147,3),$O$21:$O$147,0),"")
A15: =IF(L15="","",INDEX($A$21:$A$147,L15)) | B15: =IF(L15="","",INDEX($N$21:$N$147,L15)) | C15: =IF(L15="","",INDEX($M$21:$M$147,L15)) | D15: =IF(L15="","",INDEX($P$21:$P$147,L15)) | H15: =IF(L15="","",INDEX($Q$21:$Q$147,L15)) | L15: =IFERROR(MATCH(LARGE($O$21:$O$147,4),$O$21:$O$147,0),"")
A16: =IF(L16="","",INDEX($A$21:$A$147,L16)) | B16: =IF(L16="","",INDEX($N$21:$N$147,L16)) | C16: =IF(L16="","",INDEX($M$21:$M$147,L16)) | D16: =IF(L16="","",INDEX($P$21:$P$147,L16)) | H16: =IF(L16="","",INDEX($Q$21:$Q$147,L16)) | L16: =IFERROR(MATCH(LARGE($O$21:$O$147,5),$O$21:$O$147,0),"")
A17: A big gap with tiny groups is noise, not a finding. Check the red 'small n' flags above and the Base row of the block before you rely on a gap.
A18: Rows with a gap are highlighted amber when the gap reaches the threshold set on Start_Here. (Columns N to Q hold hidden helper formulas for this table.)
A21: Q2. Which best describes what you do right now?
A22: Base = respondents in the group who answered the question | B22: Count | H22: Column % (within group) | M22: Gap (max - min)
B23: =$A$5 -> 18 to 24 | C23: =$A$6 -> 25 to 34 | D23: =$A$7 -> 35 to 44 | E23: =$A$8 -> 45 or older | F23: All | H23: =$A$5 -> 18 to 24 | I23: =$A$6 -> 25 to 34 | J23: =$A$7 -> 35 to 44 | K23: =$A$8 -> 45 or older | L23: All
A24: Base (n answering) | B24: =COUNTIFS(Responses!$B$2:$B$1000,$A$5,Responses!$C$2:$C$1000,"<>") -> 0 | C24: =COUNTIFS(Responses!$B$2:$B$1000,$A$6,Responses!$C$2:$C$1000,"<>") -> 0 | D24: =COUNTIFS(Responses!$B$2:$B$1000,$A$7,Responses!$C$2:$C$1000,"<>") -> 0 | E24: =COUNTIFS(Responses!$B$2:$B$1000,$A$8,Responses!$C$2:$C$1000,"<>") -> 0 | F24: =COUNTA(Responses!$C$2:$C$1000) -> 0
A25: Student only | B25: =COUNTIFS(Responses!$C$2:$C$1000,$A25,Responses!$B$2:$B$1000,$A$5) -> 0 | C25: =COUNTIFS(Responses!$C$2:$C$1000,$A25,Responses!$B$2:$B$1000,$A$6) -> 0 | D25: =COUNTIFS(Responses!$C$2:$C$1000,$A25,Responses!$B$2:$B$1000,$A$7) -> 0 | E25: =COUNTIFS(Responses!$C$2:$C$1000,$A25,Responses!$B$2:$B$1000,$A$8) -> 0 | F25: =COUNTIF(Responses!$C$2:$C$1000,$A25) -> 0 | H25: =IF(B$24=0,"",B25/B$24) | I25: =IF(C$24=0,"",C25/C$24) | J25: =IF(D$24=0,"",D25/D$24) | K25: =IF(E$24=0,"",E25/E$24) | L25: =IF(F$24=0,"",F25/F$24) | M25: =IF(COUNT(H25:K25)<2,"",MAX(H25:K25)-MIN(H25:K25)) | N25: Q2 | O25: =IF(M25="","",M25+ROW()/1000000000) | P25: =IF(M25="","",INDEX($A$5:$A$8,MATCH(MAX(H25:K25),H25:K25,0))) | Q25: =IF(M25="","",INDEX($A$5:$A$8,MATCH(MIN(H25:K25),H25:K25,0)))
A26: Employed only (full-time or part-time) | B26: =COUNTIFS(Responses!$C$2:$C$1000,$A26,Responses!$B$2:$B$1000,$A$5) -> 0 | C26: =COUNTIFS(Responses!$C$2:$C$1000,$A26,Responses!$B$2:$B$1000,$A$6) -> 0 | D26: =COUNTIFS(Responses!$C$2:$C$1000,$A26,Responses!$B$2:$B$1000,$A$7) -> 0 | E26: =COUNTIFS(Responses!$C$2:$C$1000,$A26,Responses!$B$2:$B$1000,$A$8) -> 0 | F26: =COUNTIF(Responses!$C$2:$C$1000,$A26) -> 0 | H26: =IF(B$24=0,"",B26/B$24) | I26: =IF(C$24=0,"",C26/C$24) | J26: =IF(D$24=0,"",D26/D$24) | K26: =IF(E$24=0,"",E26/E$24) | L26: =IF(F$24=0,"",F26/F$24) | M26: =IF(COUNT(H26:K26)<2,"",MAX(H26:K26)-MIN(H26:K26)) | N26: Q2 | O26: =IF(M26="","",M26+ROW()/1000000000) | P26: =IF(M26="","",INDEX($A$5:$A$8,MATCH(MAX(H26:K26),H26:K26,0))) | Q26: =IF(M26="","",INDEX($A$5:$A$8,MATCH(MIN(H26:K26),H26:K26,0)))
A27: Both student and employed | B27: =COUNTIFS(Responses!$C$2:$C$1000,$A27,Responses!$B$2:$B$1000,$A$5) -> 0 | C27: =COUNTIFS(Responses!$C$2:$C$1000,$A27,Responses!$B$2:$B$1000,$A$6) -> 0 | D27: =COUNTIFS(Responses!$C$2:$C$1000,$A27,Responses!$B$2:$B$1000,$A$7) -> 0 | E27: =COUNTIFS(Responses!$C$2:$C$1000,$A27,Responses!$B$2:$B$1000,$A$8) -> 0 | F27: =COUNTIF(Responses!$C$2:$C$1000,$A27) -> 0 | H27: =IF(B$24=0,"",B27/B$24) | I27: =IF(C$24=0,"",C27/C$24) | J27: =IF(D$24=0,"",D27/D$24) | K27: =IF(E$24=0,"",E27/E$24) | L27: =IF(F$24=0,"",F27/F$24) | M27: =IF(COUNT(H27:K27)<2,"",MAX(H27:K27)-MIN(H27:K27)) | N27: Q2 | O27: =IF(M27="","",M27+ROW()/1000000000) | P27: =IF(M27="","",INDEX($A$5:$A$8,MATCH(MAX(H27:K27),H27:K27,0))) | Q27: =IF(M27="","",INDEX($A$5:$A$8,MATCH(MIN(H27:K27),H27:K27,0)))
A28: Neither at the moment | B28: =COUNTIFS(Responses!$C$2:$C$1000,$A28,Responses!$B$2:$B$1000,$A$5) -> 0 | C28: =COUNTIFS(Responses!$C$2:$C$1000,$A28,Responses!$B$2:$B$1000,$A$6) -> 0 | D28: =COUNTIFS(Responses!$C$2:$C$1000,$A28,Responses!$B$2:$B$1000,$A$7) -> 0 | E28: =COUNTIFS(Responses!$C$2:$C$1000,$A28,Responses!$B$2:$B$1000,$A$8) -> 0 | F28: =COUNTIF(Responses!$C$2:$C$1000,$A28) -> 0 | H28: =IF(B$24=0,"",B28/B$24) | I28: =IF(C$24=0,"",C28/C$24) | J28: =IF(D$24=0,"",D28/D$24) | K28: =IF(E$24=0,"",E28/E$24) | L28: =IF(F$24=0,"",F28/F$24) | M28: =IF(COUNT(H28:K28)<2,"",MAX(H28:K28)-MIN(H28:K28)) | N28: Q2 | O28: =IF(M28="","",M28+ROW()/1000000000) | P28: =IF(M28="","",INDEX($A$5:$A$8,MATCH(MAX(H28:K28),H28:K28,0))) | Q28: =IF(M28="","",INDEX($A$5:$A$8,MATCH(MIN(H28:K28),H28:K28,0)))
A31: Q3. How often do you use generative AI tools (for example ChatGPT, Copilot, Gemini or Claude) for work or study?
A32: Base = respondents in the group who answered the question | B32: Count | H32: Column % (within group) | M32: Gap (max - min)
B33: =$A$5 -> 18 to 24 | C33: =$A$6 -> 25 to 34 | D33: =$A$7 -> 35 to 44 | E33: =$A$8 -> 45 or older | F33: All | H33: =$A$5 -> 18 to 24 | I33: =$A$6 -> 25 to 34 | J33: =$A$7 -> 35 to 44 | K33: =$A$8 -> 45 or older | L33: All
A34: Base (n answering) | B34: =COUNTIFS(Responses!$B$2:$B$1000,$A$5,Responses!$D$2:$D$1000,"<>") -> 0 | C34: =COUNTIFS(Responses!$B$2:$B$1000,$A$6,Responses!$D$2:$D$1000,"<>") -> 0 | D34: =COUNTIFS(Responses!$B$2:$B$1000,$A$7,Responses!$D$2:$D$1000,"<>") -> 0 | E34: =COUNTIFS(Responses!$B$2:$B$1000,$A$8,Responses!$D$2:$D$1000,"<>") -> 0 | F34: =COUNTA(Responses!$D$2:$D$1000) -> 0
A35: Never | B35: =COUNTIFS(Responses!$D$2:$D$1000,$A35,Responses!$B$2:$B$1000,$A$5) -> 0 | C35: =COUNTIFS(Responses!$D$2:$D$1000,$A35,Responses!$B$2:$B$1000,$A$6) -> 0 | D35: =COUNTIFS(Responses!$D$2:$D$1000,$A35,Responses!$B$2:$B$1000,$A$7) -> 0 | E35: =COUNTIFS(Responses!$D$2:$D$1000,$A35,Responses!$B$2:$B$1000,$A$8) -> 0 | F35: =COUNTIF(Responses!$D$2:$D$1000,$A35) -> 0 | H35: =IF(B$34=0,"",B35/B$34) | I35: =IF(C$34=0,"",C35/C$34) | J35: =IF(D$34=0,"",D35/D$34) | K35: =IF(E$34=0,"",E35/E$34) | L35: =IF(F$34=0,"",F35/F$34) | M35: =IF(COUNT(H35:K35)<2,"",MAX(H35:K35)-MIN(H35:K35)) | N35: Q3 | O35: =IF(M35="","",M35+ROW()/1000000000) | P35: =IF(M35="","",INDEX($A$5:$A$8,MATCH(MAX(H35:K35),H35:K35,0))) | Q35: =IF(M35="","",INDEX($A$5:$A$8,MATCH(MIN(H35:K35),H35:K35,0)))
A36: Less than once a month | B36: =COUNTIFS(Responses!$D$2:$D$1000,$A36,Responses!$B$2:$B$1000,$A$5) -> 0 | C36: =COUNTIFS(Responses!$D$2:$D$1000,$A36,Responses!$B$2:$B$1000,$A$6) -> 0 | D36: =COUNTIFS(Responses!$D$2:$D$1000,$A36,Responses!$B$2:$B$1000,$A$7) -> 0 | E36: =COUNTIFS(Responses!$D$2:$D$1000,$A36,Responses!$B$2:$B$1000,$A$8) -> 0 | F36: =COUNTIF(Responses!$D$2:$D$1000,$A36) -> 0 | H36: =IF(B$34=0,"",B36/B$34) | I36: =IF(C$34=0,"",C36/C$34) | J36: =IF(D$34=0,"",D36/D$34) | K36: =IF(E$34=0,"",E36/E$34) | L36: =IF(F$34=0,"",F36/F$34) | M36: =IF(COUNT(H36:K36)<2,"",MAX(H36:K36)-MIN(H36:K36)) | N36: Q3 | O36: =IF(M36="","",M36+ROW()/1000000000) | P36: =IF(M36="","",INDEX($A$5:$A$8,MATCH(MAX(H36:K36),H36:K36,0))) | Q36: =IF(M36="","",INDEX($A$5:$A$8,MATCH(MIN(H36:K36),H36:K36,0)))
A37: A few times a month | B37: =COUNTIFS(Responses!$D$2:$D$1000,$A37,Responses!$B$2:$B$1000,$A$5) -> 0 | C37: =COUNTIFS(Responses!$D$2:$D$1000,$A37,Responses!$B$2:$B$1000,$A$6) -> 0 | D37: =COUNTIFS(Responses!$D$2:$D$1000,$A37,Responses!$B$2:$B$1000,$A$7) -> 0 | E37: =COUNTIFS(Responses!$D$2:$D$1000,$A37,Responses!$B$2:$B$1000,$A$8) -> 0 | F37: =COUNTIF(Responses!$D$2:$D$1000,$A37) -> 0 | H37: =IF(B$34=0,"",B37/B$34) | I37: =IF(C$34=0,"",C37/C$34) | J37: =IF(D$34=0,"",D37/D$34) | K37: =IF(E$34=0,"",E37/E$34) | L37: =IF(F$34=0,"",F37/F$34) | M37: =IF(COUNT(H37:K37)<2,"",MAX(H37:K37)-MIN(H37:K37)) | N37: Q3 | O37: =IF(M37="","",M37+ROW()/1000000000) | P37: =IF(M37="","",INDEX($A$5:$A$8,MATCH(MAX(H37:K37),H37:K37,0))) | Q37: =IF(M37="","",INDEX($A$5:$A$8,MATCH(MIN(H37:K37),H37:K37,0)))
A38: A few times a week | B38: =COUNTIFS(Responses!$D$2:$D$1000,$A38,Responses!$B$2:$B$1000,$A$5) -> 0 | C38: =COUNTIFS(Responses!$D$2:$D$1000,$A38,Responses!$B$2:$B$1000,$A$6) -> 0 | D38: =COUNTIFS(Responses!$D$2:$D$1000,$A38,Responses!$B$2:$B$1000,$A$7) -> 0 | E38: =COUNTIFS(Responses!$D$2:$D$1000,$A38,Responses!$B$2:$B$1000,$A$8) -> 0 | F38: =COUNTIF(Responses!$D$2:$D$1000,$A38) -> 0 | H38: =IF(B$34=0,"",B38/B$34) | I38: =IF(C$34=0,"",C38/C$34) | J38: =IF(D$34=0,"",D38/D$34) | K38: =IF(E$34=0,"",E38/E$34) | L38: =IF(F$34=0,"",F38/F$34) | M38: =IF(COUNT(H38:K38)<2,"",MAX(H38:K38)-MIN(H38:K38)) | N38: Q3 | O38: =IF(M38="","",M38+ROW()/1000000000) | P38: =IF(M38="","",INDEX($A$5:$A$8,MATCH(MAX(H38:K38),H38:K38,0))) | Q38: =IF(M38="","",INDEX($A$5:$A$8,MATCH(MIN(H38:K38),H38:K38,0)))
A39: Daily | B39: =COUNTIFS(Responses!$D$2:$D$1000,$A39,Responses!$B$2:$B$1000,$A$5) -> 0 | C39: =COUNTIFS(Responses!$D$2:$D$1000,$A39,Responses!$B$2:$B$1000,$A$6) -> 0 | D39: =COUNTIFS(Responses!$D$2:$D$1000,$A39,Responses!$B$2:$B$1000,$A$7) -> 0 | E39: =COUNTIFS(Responses!$D$2:$D$1000,$A39,Responses!$B$2:$B$1000,$A$8) -> 0 | F39: =COUNTIF(Responses!$D$2:$D$1000,$A39) -> 0 | H39: =IF(B$34=0,"",B39/B$34) | I39: =IF(C$34=0,"",C39/C$34) | J39: =IF(D$34=0,"",D39/D$34) | K39: =IF(E$34=0,"",E39/E$34) | L39: =IF(F$34=0,"",F39/F$34) | M39: =IF(COUNT(H39:K39)<2,"",MAX(H39:K39)-MIN(H39:K39)) | N39: Q3 | O39: =IF(M39="","",M39+ROW()/1000000000) | P39: =IF(M39="","",INDEX($A$5:$A$8,MATCH(MAX(H39:K39),H39:K39,0))) | Q39: =IF(M39="","",INDEX($A$5:$A$8,MATCH(MIN(H39:K39),H39:K39,0)))
A42: Q4. Which tasks do you use AI tools for? Select all that apply.
A43: Base = respondents in the group who answered the question | B43: Count | H43: Column % (within group) | M43: Gap (max - min)
B44: =$A$5 -> 18 to 24 | C44: =$A$6 -> 25 to 34 | D44: =$A$7 -> 35 to 44 | E44: =$A$8 -> 45 or older | F44: All | H44: =$A$5 -> 18 to 24 | I44: =$A$6 -> 25 to 34 | J44: =$A$7 -> 35 to 44 | K44: =$A$8 -> 45 or older | L44: All
A45: Base (n answering) | B45: =COUNTIFS(Responses!$B$2:$B$1000,$A$5,Responses!$E$2:$E$1000,"<>") -> 0 | C45: =COUNTIFS(Responses!$B$2:$B$1000,$A$6,Responses!$E$2:$E$1000,"<>") -> 0 | D45: =COUNTIFS(Responses!$B$2:$B$1000,$A$7,Responses!$E$2:$E$1000,"<>") -> 0 | E45: =COUNTIFS(Responses!$B$2:$B$1000,$A$8,Responses!$E$2:$E$1000,"<>") -> 0 | F45: =COUNTA(Responses!$E$2:$E$1000) -> 0
A46: Writing or editing | B46: =COUNTIFS(Responses!$E$2:$E$1000,"*"&$A46&"*",Responses!$B$2:$B$1000,$A$5) -> 0 | C46: =COUNTIFS(Responses!$E$2:$E$1000,"*"&$A46&"*",Responses!$B$2:$B$1000,$A$6) -> 0 | D46: =COUNTIFS(Responses!$E$2:$E$1000,"*"&$A46&"*",Responses!$B$2:$B$1000,$A$7) -> 0 | E46: =COUNTIFS(Responses!$E$2:$E$1000,"*"&$A46&"*",Responses!$B$2:$B$1000,$A$8) -> 0 | F46: =COUNTIF(Responses!$E$2:$E$1000,"*"&$A46&"*") -> 0 | H46: =IF(B$45=0,"",B46/B$45) | I46: =IF(C$45=0,"",C46/C$45) | J46: =IF(D$45=0,"",D46/D$45) | K46: =IF(E$45=0,"",E46/E$45) | L46: =IF(F$45=0,"",F46/F$45) | M46: =IF(COUNT(H46:K46)<2,"",MAX(H46:K46)-MIN(H46:K46)) | N46: Q4 | O46: =IF(M46="","",M46+ROW()/1000000000) | P46: =IF(M46="","",INDEX($A$5:$A$8,MATCH(MAX(H46:K46),H46:K46,0))) | Q46: =IF(M46="","",INDEX($A$5:$A$8,MATCH(MIN(H46:K46),H46:K46,0)))
A47: Research or summarizing | B47: =COUNTIFS(Responses!$E$2:$E$1000,"*"&$A47&"*",Responses!$B$2:$B$1000,$A$5) -> 0 | C47: =COUNTIFS(Responses!$E$2:$E$1000,"*"&$A47&"*",Responses!$B$2:$B$1000,$A$6) -> 0 | D47: =COUNTIFS(Responses!$E$2:$E$1000,"*"&$A47&"*",Responses!$B$2:$B$1000,$A$7) -> 0 | E47: =COUNTIFS(Responses!$E$2:$E$1000,"*"&$A47&"*",Responses!$B$2:$B$1000,$A$8) -> 0 | F47: =COUNTIF(Responses!$E$2:$E$1000,"*"&$A47&"*") -> 0 | H47: =IF(B$45=0,"",B47/B$45) | I47: =IF(C$45=0,"",C47/C$45) | J47: =IF(D$45=0,"",D47/D$45) | K47: =IF(E$45=0,"",E47/E$45) | L47: =IF(F$45=0,"",F47/F$45) | M47: =IF(COUNT(H47:K47)<2,"",MAX(H47:K47)-MIN(H47:K47)) | N47: Q4 | O47: =IF(M47="","",M47+ROW()/1000000000) | P47: =IF(M47="","",INDEX($A$5:$A$8,MATCH(MAX(H47:K47),H47:K47,0))) | Q47: =IF(M47="","",INDEX($A$5:$A$8,MATCH(MIN(H47:K47),H47:K47,0)))
A48: Brainstorming ideas | B48: =COUNTIFS(Responses!$E$2:$E$1000,"*"&$A48&"*",Responses!$B$2:$B$1000,$A$5) -> 0 | C48: =COUNTIFS(Responses!$E$2:$E$1000,"*"&$A48&"*",Responses!$B$2:$B$1000,$A$6) -> 0 | D48: =COUNTIFS(Responses!$E$2:$E$1000,"*"&$A48&"*",Responses!$B$2:$B$1000,$A$7) -> 0 | E48: =COUNTIFS(Responses!$E$2:$E$1000,"*"&$A48&"*",Responses!$B$2:$B$1000,$A$8) -> 0 | F48: =COUNTIF(Responses!$E$2:$E$1000,"*"&$A48&"*") -> 0 | H48: =IF(B$45=0,"",B48/B$45) | I48: =IF(C$45=0,"",C48/C$45) | J48: =IF(D$45=0,"",D48/D$45) | K48: =IF(E$45=0,"",E48/E$45) | L48: =IF(F$45=0,"",F48/F$45) | M48: =IF(COUNT(H48:K48)<2,"",MAX(H48:K48)-MIN(H48:K48)) | N48: Q4 | O48: =IF(M48="","",M48+ROW()/1000000000) | P48: =IF(M48="","",INDEX($A$5:$A$8,MATCH(MAX(H48:K48),H48:K48,0))) | Q48: =IF(M48="","",INDEX($A$5:$A$8,MATCH(MIN(H48:K48),H48:K48,0)))
...

Sheet XTab_Role
A1: Cross-tabs by main activity (Q2)
A2: Do answers differ between students and workers? Percentages are within each group.
A4: Group | B4: n | C4: % of sample | D4: Flag
A5: Student only | B5: =COUNTIF(Responses!$C$2:$C$1000,A5) -> 0 | C5: =IF(Start_Here!$C$19=0,"",B5/Start_Here!$C$19) | D5: =IF(B5<Start_Here!$C$15,"small n","") -> small n
A6: Employed only (full-time or part-time) | B6: =COUNTIF(Responses!$C$2:$C$1000,A6) -> 0 | C6: =IF(Start_Here!$C$19=0,"",B6/Start_Here!$C$19) | D6: =IF(B6<Start_Here!$C$15,"small n","") -> small n
A7: Both student and employed | B7: =COUNTIF(Responses!$C$2:$C$1000,A7) -> 0 | C7: =IF(Start_Here!$C$19=0,"",B7/Start_Here!$C$19) | D7: =IF(B7<Start_Here!$C$15,"small n","") -> small n
A8: Neither at the moment | B8: =COUNTIF(Responses!$C$2:$C$1000,A8) -> 0 | C8: =IF(Start_Here!$C$19=0,"",B8/Start_Here!$C$19) | D8: =IF(B8<Start_Here!$C$15,"small n","") -> small n
A10: Largest differences between groups (top 5, in percentage points)
A11: Row (question / option) | B11: Qn | C11: Gap | D11: Highest group | H11: Lowest group | L11: (row ref)
A12: =IF(L12="","",INDEX($A$21:$A$147,L12)) | B12: =IF(L12="","",INDEX($N$21:$N$147,L12)) | C12: =IF(L12="","",INDEX($M$21:$M$147,L12)) | D12: =IF(L12="","",INDEX($P$21:$P$147,L12)) | H12: =IF(L12="","",INDEX($Q$21:$Q$147,L12)) | L12: =IFERROR(MATCH(LARGE($O$21:$O$147,1),$O$21:$O$147,0),"")
A13: =IF(L13="","",INDEX($A$21:$A$147,L13)) | B13: =IF(L13="","",INDEX($N$21:$N$147,L13)) | C13: =IF(L13="","",INDEX($M$21:$M$147,L13)) | D13: =IF(L13="","",INDEX($P$21:$P$147,L13)) | H13: =IF(L13="","",INDEX($Q$21:$Q$147,L13)) | L13: =IFERROR(MATCH(LARGE($O$21:$O$147,2),$O$21:$O$147,0),"")
A14: =IF(L14="","",INDEX($A$21:$A$147,L14)) | B14: =IF(L14="","",INDEX($N$21:$N$147,L14)) | C14: =IF(L14="","",INDEX($M$21:$M$147,L14)) | D14: =IF(L14="","",INDEX($P$21:$P$147,L14)) | H14: =IF(L14="","",INDEX($Q$21:$Q$147,L14)) | L14: =IFERROR(MATCH(LARGE($O$21:$O$147,3),$O$21:$O$147,0),"")
A15: =IF(L15="","",INDEX($A$21:$A$147,L15)) | B15: =IF(L15="","",INDEX($N$21:$N$147,L15)) | C15: =IF(L15="","",INDEX($M$21:$M$147,L15)) | D15: =IF(L15="","",INDEX($P$21:$P$147,L15)) | H15: =IF(L15="","",INDEX($Q$21:$Q$147,L15)) | L15: =IFERROR(MATCH(LARGE($O$21:$O$147,4),$O$21:$O$147,0),"")
A16: =IF(L16="","",INDEX($A$21:$A$147,L16)) | B16: =IF(L16="","",INDEX($N$21:$N$147,L16)) | C16: =IF(L16="","",INDEX($M$21:$M$147,L16)) | D16: =IF(L16="","",INDEX($P$21:$P$147,L16)) | H16: =IF(L16="","",INDEX($Q$21:$Q$147,L16)) | L16: =IFERROR(MATCH(LARGE($O$21:$O$147,5),$O$21:$O$147,0),"")
A17: A big gap with tiny groups is noise, not a finding. Check the red 'small n' flags above and the Base row of the block before you rely on a gap.
A18: Rows with a gap are highlighted amber when the gap reaches the threshold set on Start_Here. (Columns N to Q hold hidden helper formulas for this table.)
A21: Q1. Which age group are you in?
A22: Base = respondents in the group who answered the question | B22: Count | H22: Column % (within group) | M22: Gap (max - min)
B23: =$A$5 -> Student only | C23: =$A$6 -> Employed only (full-time or part-time) | D23: =$A$7 -> Both student and employed | E23: =$A$8 -> Neither at the moment | F23: All | H23: =$A$5 -> Student only | I23: =$A$6 -> Employed only (full-time or part-time) | J23: =$A$7 -> Both student and employed | K23: =$A$8 -> Neither at the moment | L23: All
A24: Base (n answering) | B24: =COUNTIFS(Responses!$C$2:$C$1000,$A$5,Responses!$B$2:$B$1000,"<>") -> 0 | C24: =COUNTIFS(Responses!$C$2:$C$1000,$A$6,Responses!$B$2:$B$1000,"<>") -> 0 | D24: =COUNTIFS(Responses!$C$2:$C$1000,$A$7,Responses!$B$2:$B$1000,"<>") -> 0 | E24: =COUNTIFS(Responses!$C$2:$C$1000,$A$8,Responses!$B$2:$B$1000,"<>") -> 0 | F24: =COUNTA(Responses!$B$2:$B$1000) -> 0
A25: 18 to 24 | B25: =COUNTIFS(Responses!$B$2:$B$1000,$A25,Responses!$C$2:$C$1000,$A$5) -> 0 | C25: =COUNTIFS(Responses!$B$2:$B$1000,$A25,Responses!$C$2:$C$1000,$A$6) -> 0 | D25: =COUNTIFS(Responses!$B$2:$B$1000,$A25,Responses!$C$2:$C$1000,$A$7) -> 0 | E25: =COUNTIFS(Responses!$B$2:$B$1000,$A25,Responses!$C$2:$C$1000,$A$8) -> 0 | F25: =COUNTIF(Responses!$B$2:$B$1000,$A25) -> 0 | H25: =IF(B$24=0,"",B25/B$24) | I25: =IF(C$24=0,"",C25/C$24) | J25: =IF(D$24=0,"",D25/D$24) | K25: =IF(E$24=0,"",E25/E$24) | L25: =IF(F$24=0,"",F25/F$24) | M25: =IF(COUNT(H25:K25)<2,"",MAX(H25:K25)-MIN(H25:K25)) | N25: Q1 | O25: =IF(M25="","",M25+ROW()/1000000000) | P25: =IF(M25="","",INDEX($A$5:$A$8,MATCH(MAX(H25:K25),H25:K25,0))) | Q25: =IF(M25="","",INDEX($A$5:$A$8,MATCH(MIN(H25:K25),H25:K25,0)))
A26: 25 to 34 | B26: =COUNTIFS(Responses!$B$2:$B$1000,$A26,Responses!$C$2:$C$1000,$A$5) -> 0 | C26: =COUNTIFS(Responses!$B$2:$B$1000,$A26,Responses!$C$2:$C$1000,$A$6) -> 0 | D26: =COUNTIFS(Responses!$B$2:$B$1000,$A26,Responses!$C$2:$C$1000,$A$7) -> 0 | E26: =COUNTIFS(Responses!$B$2:$B$1000,$A26,Responses!$C$2:$C$1000,$A$8) -> 0 | F26: =COUNTIF(Responses!$B$2:$B$1000,$A26) -> 0 | H26: =IF(B$24=0,"",B26/B$24) | I26: =IF(C$24=0,"",C26/C$24) | J26: =IF(D$24=0,"",D26/D$24) | K26: =IF(E$24=0,"",E26/E$24) | L26: =IF(F$24=0,"",F26/F$24) | M26: =IF(COUNT(H26:K26)<2,"",MAX(H26:K26)-MIN(H26:K26)) | N26: Q1 | O26: =IF(M26="","",M26+ROW()/1000000000) | P26: =IF(M26="","",INDEX($A$5:$A$8,MATCH(MAX(H26:K26),H26:K26,0))) | Q26: =IF(M26="","",INDEX($A$5:$A$8,MATCH(MIN(H26:K26),H26:K26,0)))
A27: 35 to 44 | B27: =COUNTIFS(Responses!$B$2:$B$1000,$A27,Responses!$C$2:$C$1000,$A$5) -> 0 | C27: =COUNTIFS(Responses!$B$2:$B$1000,$A27,Responses!$C$2:$C$1000,$A$6) -> 0 | D27: =COUNTIFS(Responses!$B$2:$B$1000,$A27,Responses!$C$2:$C$1000,$A$7) -> 0 | E27: =COUNTIFS(Responses!$B$2:$B$1000,$A27,Responses!$C$2:$C$1000,$A$8) -> 0 | F27: =COUNTIF(Responses!$B$2:$B$1000,$A27) -> 0 | H27: =IF(B$24=0,"",B27/B$24) | I27: =IF(C$24=0,"",C27/C$24) | J27: =IF(D$24=0,"",D27/D$24) | K27: =IF(E$24=0,"",E27/E$24) | L27: =IF(F$24=0,"",F27/F$24) | M27: =IF(COUNT(H27:K27)<2,"",MAX(H27:K27)-MIN(H27:K27)) | N27: Q1 | O27: =IF(M27="","",M27+ROW()/1000000000) | P27: =IF(M27="","",INDEX($A$5:$A$8,MATCH(MAX(H27:K27),H27:K27,0))) | Q27: =IF(M27="","",INDEX($A$5:$A$8,MATCH(MIN(H27:K27),H27:K27,0)))
A28: 45 or older | B28: =COUNTIFS(Responses!$B$2:$B$1000,$A28,Responses!$C$2:$C$1000,$A$5) -> 0 | C28: =COUNTIFS(Responses!$B$2:$B$1000,$A28,Responses!$C$2:$C$1000,$A$6) -> 0 | D28: =COUNTIFS(Responses!$B$2:$B$1000,$A28,Responses!$C$2:$C$1000,$A$7) -> 0 | E28: =COUNTIFS(Responses!$B$2:$B$1000,$A28,Responses!$C$2:$C$1000,$A$8) -> 0 | F28: =COUNTIF(Responses!$B$2:$B$1000,$A28) -> 0 | H28: =IF(B$24=0,"",B28/B$24) | I28: =IF(C$24=0,"",C28/C$24) | J28: =IF(D$24=0,"",D28/D$24) | K28: =IF(E$24=0,"",E28/E$24) | L28: =IF(F$24=0,"",F28/F$24) | M28: =IF(COUNT(H28:K28)<2,"",MAX(H28:K28)-MIN(H28:K28)) | N28: Q1 | O28: =IF(M28="","",M28+ROW()/1000000000) | P28: =IF(M28="","",INDEX($A$5:$A$8,MATCH(MAX(H28:K28),H28:K28,0))) | Q28: =IF(M28="","",INDEX($A$5:$A$8,MATCH(MIN(H28:K28),H28:K28,0)))
A31: Q3. How often do you use generative AI tools (for example ChatGPT, Copilot, Gemini or Claude) for work or study?
A32: Base = respondents in the group who answered the question | B32: Count | H32: Column % (within group) | M32: Gap (max - min)
B33: =$A$5 -> Student only | C33: =$A$6 -> Employed only (full-time or part-time) | D33: =$A$7 -> Both student and employed | E33: =$A$8 -> Neither at the moment | F33: All | H33: =$A$5 -> Student only | I33: =$A$6 -> Employed only (full-time or part-time) | J33: =$A$7 -> Both student and employed | K33: =$A$8 -> Neither at the moment | L33: All
A34: Base (n answering) | B34: =COUNTIFS(Responses!$C$2:$C$1000,$A$5,Responses!$D$2:$D$1000,"<>") -> 0 | C34: =COUNTIFS(Responses!$C$2:$C$1000,$A$6,Responses!$D$2:$D$1000,"<>") -> 0 | D34: =COUNTIFS(Responses!$C$2:$C$1000,$A$7,Responses!$D$2:$D$1000,"<>") -> 0 | E34: =COUNTIFS(Responses!$C$2:$C$1000,$A$8,Responses!$D$2:$D$1000,"<>") -> 0 | F34: =COUNTA(Responses!$D$2:$D$1000) -> 0
A35: Never | B35: =COUNTIFS(Responses!$D$2:$D$1000,$A35,Responses!$C$2:$C$1000,$A$5) -> 0 | C35: =COUNTIFS(Responses!$D$2:$D$1000,$A35,Responses!$C$2:$C$1000,$A$6) -> 0 | D35: =COUNTIFS(Responses!$D$2:$D$1000,$A35,Responses!$C$2:$C$1000,$A$7) -> 0 | E35: =COUNTIFS(Responses!$D$2:$D$1000,$A35,Responses!$C$2:$C$1000,$A$8) -> 0 | F35: =COUNTIF(Responses!$D$2:$D$1000,$A35) -> 0 | H35: =IF(B$34=0,"",B35/B$34) | I35: =IF(C$34=0,"",C35/C$34) | J35: =IF(D$34=0,"",D35/D$34) | K35: =IF(E$34=0,"",E35/E$34) | L35: =IF(F$34=0,"",F35/F$34) | M35: =IF(COUNT(H35:K35)<2,"",MAX(H35:K35)-MIN(H35:K35)) | N35: Q3 | O35: =IF(M35="","",M35+ROW()/1000000000) | P35: =IF(M35="","",INDEX($A$5:$A$8,MATCH(MAX(H35:K35),H35:K35,0))) | Q35: =IF(M35="","",INDEX($A$5:$A$8,MATCH(MIN(H35:K35),H35:K35,0)))
A36: Less than once a month | B36: =COUNTIFS(Responses!$D$2:$D$1000,$A36,Responses!$C$2:$C$1000,$A$5) -> 0 | C36: =COUNTIFS(Responses!$D$2:$D$1000,$A36,Responses!$C$2:$C$1000,$A$6) -> 0 | D36: =COUNTIFS(Responses!$D$2:$D$1000,$A36,Responses!$C$2:$C$1000,$A$7) -> 0 | E36: =COUNTIFS(Responses!$D$2:$D$1000,$A36,Responses!$C$2:$C$1000,$A$8) -> 0 | F36: =COUNTIF(Responses!$D$2:$D$1000,$A36) -> 0 | H36: =IF(B$34=0,"",B36/B$34) | I36: =IF(C$34=0,"",C36/C$34) | J36: =IF(D$34=0,"",D36/D$34) | K36: =IF(E$34=0,"",E36/E$34) | L36: =IF(F$34=0,"",F36/F$34) | M36: =IF(COUNT(H36:K36)<2,"",MAX(H36:K36)-MIN(H36:K36)) | N36: Q3 | O36: =IF(M36="","",M36+ROW()/1000000000) | P36: =IF(M36="","",INDEX($A$5:$A$8,MATCH(MAX(H36:K36),H36:K36,0))) | Q36: =IF(M36="","",INDEX($A$5:$A$8,MATCH(MIN(H36:K36),H36:K36,0)))
A37: A few times a month | B37: =COUNTIFS(Responses!$D$2:$D$1000,$A37,Responses!$C$2:$C$1000,$A$5) -> 0 | C37: =COUNTIFS(Responses!$D$2:$D$1000,$A37,Responses!$C$2:$C$1000,$A$6) -> 0 | D37: =COUNTIFS(Responses!$D$2:$D$1000,$A37,Responses!$C$2:$C$1000,$A$7) -> 0 | E37: =COUNTIFS(Responses!$D$2:$D$1000,$A37,Responses!$C$2:$C$1000,$A$8) -> 0 | F37: =COUNTIF(Responses!$D$2:$D$1000,$A37) -> 0 | H37: =IF(B$34=0,"",B37/B$34) | I37: =IF(C$34=0,"",C37/C$34) | J37: =IF(D$34=0,"",D37/D$34) | K37: =IF(E$34=0,"",E37/E$34) | L37: =IF(F$34=0,"",F37/F$34) | M37: =IF(COUNT(H37:K37)<2,"",MAX(H37:K37)-MIN(H37:K37)) | N37: Q3 | O37: =IF(M37="","",M37+ROW()/1000000000) | P37: =IF(M37="","",INDEX($A$5:$A$8,MATCH(MAX(H37:K37),H37:K37,0))) | Q37: =IF(M37="","",INDEX($A$5:$A$8,MATCH(MIN(H37:K37),H37:K37,0)))
A38: A few times a week | B38: =COUNTIFS(Responses!$D$2:$D$1000,$A38,Responses!$C$2:$C$1000,$A$5) -> 0 | C38: =COUNTIFS(Responses!$D$2:$D$1000,$A38,Responses!$C$2:$C$1000,$A$6) -> 0 | D38: =COUNTIFS(Responses!$D$2:$D$1000,$A38,Responses!$C$2:$C$1000,$A$7) -> 0 | E38: =COUNTIFS(Responses!$D$2:$D$1000,$A38,Responses!$C$2:$C$1000,$A$8) -> 0 | F38: =COUNTIF(Responses!$D$2:$D$1000,$A38) -> 0 | H38: =IF(B$34=0,"",B38/B$34) | I38: =IF(C$34=0,"",C38/C$34) | J38: =IF(D$34=0,"",D38/D$34) | K38: =IF(E$34=0,"",E38/E$34) | L38: =IF(F$34=0,"",F38/F$34) | M38: =IF(COUNT(H38:K38)<2,"",MAX(H38:K38)-MIN(H38:K38)) | N38: Q3 | O38: =IF(M38="","",M38+ROW()/1000000000) | P38: =IF(M38="","",INDEX($A$5:$A$8,MATCH(MAX(H38:K38),H38:K38,0))) | Q38: =IF(M38="","",INDEX($A$5:$A$8,MATCH(MIN(H38:K38),H38:K38,0)))
A39: Daily | B39: =COUNTIFS(Responses!$D$2:$D$1000,$A39,Responses!$C$2:$C$1000,$A$5) -> 0 | C39: =COUNTIFS(Responses!$D$2:$D$1000,$A39,Responses!$C$2:$C$1000,$A$6) -> 0 | D39: =COUNTIFS(Responses!$D$2:$D$1000,$A39,Responses!$C$2:$C$1000,$A$7) -> 0 | E39: =COUNTIFS(Responses!$D$2:$D$1000,$A39,Responses!$C$2:$C$1000,$A$8) -> 0 | F39: =COUNTIF(Responses!$D$2:$D$1000,$A39) -> 0 | H39: =IF(B$34=0,"",B39/B$34) | I39: =IF(C$34=0,"",C39/C$34) | J39: =IF(D$34=0,"",D39/D$34) | K39: =IF(E$34=0,"",E39/E$34) | L39: =IF(F$34=0,"",F39/F$34) | M39: =IF(COUNT(H39:K39)<2,"",MAX(H39:K39)-MIN(H39:K39)) | N39: Q3 | O39: =IF(M39="","",M39+ROW()/1000000000) | P39: =IF(M39="","",INDEX($A$5:$A$8,MATCH(MAX(H39:K39),H39:K39,0))) | Q39: =IF(M39="","",INDEX($A$5:$A$8,MATCH(MIN(H39:K39),H39:K39,0)))
A42: Q4. Which tasks do you use AI tools for? Select all that apply.
A43: Base = respondents in the group who answered the question | B43: Count | H43: Column % (within group) | M43: Gap (max - min)
B44: =$A$5 -> Student only | C44: =$A$6 -> Employed only (full-time or part-time) | D44: =$A$7 -> Both student and employed | E44: =$A$8 -> Neither at the moment | F44: All | H44: =$A$5 -> Student only | I44: =$A$6 -> Employed only (full-time or part-time) | J44: =$A$7 -> Both student and employed | K44: =$A$8 -> Neither at the moment | L44: All
A45: Base (n answering) | B45: =COUNTIFS(Responses!$C$2:$C$1000,$A$5,Responses!$E$2:$E$1000,"<>") -> 0 | C45: =COUNTIFS(Responses!$C$2:$C$1000,$A$6,Responses!$E$2:$E$1000,"<>") -> 0 | D45: =COUNTIFS(Responses!$C$2:$C$1000,$A$7,Responses!$E$2:$E$1000,"<>") -> 0 | E45: =COUNTIFS(Responses!$C$2:$C$1000,$A$8,Responses!$E$2:$E$1000,"<>") -> 0 | F45: =COUNTA(Responses!$E$2:$E$1000) -> 0
A46: Writing or editing | B46: =COUNTIFS(Responses!$E$2:$E$1000,"*"&$A46&"*",Responses!$C$2:$C$1000,$A$5) -> 0 | C46: =COUNTIFS(Responses!$E$2:$E$1000,"*"&$A46&"*",Responses!$C$2:$C$1000,$A$6) -> 0 | D46: =COUNTIFS(Responses!$E$2:$E$1000,"*"&$A46&"*",Responses!$C$2:$C$1000,$A$7) -> 0 | E46: =COUNTIFS(Responses!$E$2:$E$1000,"*"&$A46&"*",Responses!$C$2:$C$1000,$A$8) -> 0 | F46: =COUNTIF(Responses!$E$2:$E$1000,"*"&$A46&"*") -> 0 | H46: =IF(B$45=0,"",B46/B$45) | I46: =IF(C$45=0,"",C46/C$45) | J46: =IF(D$45=0,"",D46/D$45) | K46: =IF(E$45=0,"",E46/E$45) | L46: =IF(F$45=0,"",F46/F$45) | M46: =IF(COUNT(H46:K46)<2,"",MAX(H46:K46)-MIN(H46:K46)) | N46: Q4 | O46: =IF(M46="","",M46+ROW()/1000000000) | P46: =IF(M46="","",INDEX($A$5:$A$8,MATCH(MAX(H46:K46),H46:K46,0))) | Q46: =IF(M46="","",INDEX($A$5:$A$8,MATCH(MIN(H46:K46),H46:K46,0)))
A47: Research or summarizing | B47: =COUNTIFS(Responses!$E$2:$E$1000,"*"&$A47&"*",Responses!$C$2:$C$1000,$A$5) -> 0 | C47: =COUNTIFS(Responses!$E$2:$E$1000,"*"&$A47&"*",Responses!$C$2:$C$1000,$A$6) -> 0 | D47: =COUNTIFS(Responses!$E$2:$E$1000,"*"&$A47&"*",Responses!$C$2:$C$1000,$A$7) -> 0 | E47: =COUNTIFS(Responses!$E$2:$E$1000,"*"&$A47&"*",Responses!$C$2:$C$1000,$A$8) -> 0 | F47: =COUNTIF(Responses!$E$2:$E$1000,"*"&$A47&"*") -> 0 | H47: =IF(B$45=0,"",B47/B$45) | I47: =IF(C$45=0,"",C47/C$45) | J47: =IF(D$45=0,"",D47/D$45) | K47: =IF(E$45=0,"",E47/E$45) | L47: =IF(F$45=0,"",F47/F$45) | M47: =IF(COUNT(H47:K47)<2,"",MAX(H47:K47)-MIN(H47:K47)) | N47: Q4 | O47: =IF(M47="","",M47+ROW()/1000000000) | P47: =IF(M47="","",INDEX($A$5:$A$8,MATCH(MAX(H47:K47),H47:K47,0))) | Q47: =IF(M47="","",INDEX($A$5:$A$8,MATCH(MIN(H47:K47),H47:K47,0)))
A48: Brainstorming ideas | B48: =COUNTIFS(Responses!$E$2:$E$1000,"*"&$A48&"*",Responses!$C$2:$C$1000,$A$5) -> 0 | C48: =COUNTIFS(Responses!$E$2:$E$1000,"*"&$A48&"*",Responses!$C$2:$C$1000,$A$6) -> 0 | D48: =COUNTIFS(Responses!$E$2:$E$1000,"*"&$A48&"*",Responses!$C$2:$C$1000,$A$7) -> 0 | E48: =COUNTIFS(Responses!$E$2:$E$1000,"*"&$A48&"*",Responses!$C$2:$C$1000,$A$8) -> 0 | F48: =COUNTIF(Responses!$E$2:$E$1000,"*"&$A48&"*") -> 0 | H48: =IF(B$45=0,"",B48/B$45) | I48: =IF(C$45=0,"",C48/C$45) | J48: =IF(D$45=0,"",D48/D$45) | K48: =IF(E$45=0,"",E48/E$45) | L48: =IF(F$45=0,"",F48/F$45) | M48: =IF(COUNT(H48:K48)<2,"",MAX(H48:K48)-MIN(H48:K48)) | N48: Q4 | O48: =IF(M48="","",M48+ROW()/1000000000) | P48: =IF(M48="","",INDEX($A$5:$A$8,MATCH(MAX(H48:K48),H48:K48,0))) | Q48: =IF(M48="","",INDEX($A$5:$A$8,MATCH(MIN(H48:K48),H48:K48,0)))
...

Sheet XTab_Guidance
A1: Cross-tabs by guidance received (Q8)
A2: Extra lens: does guidance received (Q8) go with confidence (Q7), speed/quality (Q6) and barriers (Q10)?
A4: Group | B4: n | C4: % of sample | D4: Flag
A5: Formal training | B5: =COUNTIF(Responses!$K$2:$K$1000,A5) -> 0 | C5: =IF(Start_Here!$C$19=0,"",B5/Start_Here!$C$19) | D5: =IF(B5<Start_Here!$C$15,"small n","") -> small n
A6: Written policy or guidelines only | B6: =COUNTIF(Responses!$K$2:$K$1000,A6) -> 0 | C6: =IF(Start_Here!$C$19=0,"",B6/Start_Here!$C$19) | D6: =IF(B6<Start_Here!$C$15,"small n","") -> small n
A7: Informal advice only | B7: =COUNTIF(Responses!$K$2:$K$1000,A7) -> 0 | C7: =IF(Start_Here!$C$19=0,"",B7/Start_Here!$C$19) | D7: =IF(B7<Start_Here!$C$15,"small n","") -> small n
A8: No guidance at all | B8: =COUNTIF(Responses!$K$2:$K$1000,A8) -> 0 | C8: =IF(Start_Here!$C$19=0,"",B8/Start_Here!$C$19) | D8: =IF(B8<Start_Here!$C$15,"small n","") -> small n
A10: Largest differences between groups (top 5, in percentage points)
A11: Row (question / option) | B11: Qn | C11: Gap | D11: Highest group | H11: Lowest group | L11: (row ref)
A12: =IF(L12="","",INDEX($A$21:$A$147,L12)) | B12: =IF(L12="","",INDEX($N$21:$N$147,L12)) | C12: =IF(L12="","",INDEX($M$21:$M$147,L12)) | D12: =IF(L12="","",INDEX($P$21:$P$147,L12)) | H12: =IF(L12="","",INDEX($Q$21:$Q$147,L12)) | L12: =IFERROR(MATCH(LARGE($O$21:$O$147,1),$O$21:$O$147,0),"")
A13: =IF(L13="","",INDEX($A$21:$A$147,L13)) | B13: =IF(L13="","",INDEX($N$21:$N$147,L13)) | C13: =IF(L13="","",INDEX($M$21:$M$147,L13)) | D13: =IF(L13="","",INDEX($P$21:$P$147,L13)) | H13: =IF(L13="","",INDEX($Q$21:$Q$147,L13)) | L13: =IFERROR(MATCH(LARGE($O$21:$O$147,2),$O$21:$O$147,0),"")
A14: =IF(L14="","",INDEX($A$21:$A$147,L14)) | B14: =IF(L14="","",INDEX($N$21:$N$147,L14)) | C14: =IF(L14="","",INDEX($M$21:$M$147,L14)) | D14: =IF(L14="","",INDEX($P$21:$P$147,L14)) | H14: =IF(L14="","",INDEX($Q$21:$Q$147,L14)) | L14: =IFERROR(MATCH(LARGE($O$21:$O$147,3),$O$21:$O$147,0),"")
A15: =IF(L15="","",INDEX($A$21:$A$147,L15)) | B15: =IF(L15="","",INDEX($N$21:$N$147,L15)) | C15: =IF(L15="","",INDEX($M$21:$M$147,L15)) | D15: =IF(L15="","",INDEX($P$21:$P$147,L15)) | H15: =IF(L15="","",INDEX($Q$21:$Q$147,L15)) | L15: =IFERROR(MATCH(LARGE($O$21:$O$147,4),$O$21:$O$147,0),"")
A16: =IF(L16="","",INDEX($A$21:$A$147,L16)) | B16: =IF(L16="","",INDEX($N$21:$N$147,L16)) | C16: =IF(L16="","",INDEX($M$21:$M$147,L16)) | D16: =IF(L16="","",INDEX($P$21:$P$147,L16)) | H16: =IF(L16="","",INDEX($Q$21:$Q$147,L16)) | L16: =IFERROR(MATCH(LARGE($O$21:$O$147,5),$O$21:$O$147,0),"")
A17: A big gap with tiny groups is noise, not a finding. Check the red 'small n' flags above and the Base row of the block before you rely on a gap.
A18: Rows with a gap are highlighted amber when the gap reaches the threshold set on Start_Here. (Columns N to Q hold hidden helper formulas for this table.)
A21: Q1. Which age group are you in?
A22: Base = respondents in the group who answered the question | B22: Count | H22: Column % (within group) | M22: Gap (max - min)
B23: =$A$5 -> Formal training | C23: =$A$6 -> Written policy or guidelines only | D23: =$A$7 -> Informal advice only | E23: =$A$8 -> No guidance at all | F23: All | H23: =$A$5 -> Formal training | I23: =$A$6 -> Written policy or guidelines only | J23: =$A$7 -> Informal advice only | K23: =$A$8 -> No guidance at all | L23: All
A24: Base (n answering) | B24: =COUNTIFS(Responses!$K$2:$K$1000,$A$5,Responses!$B$2:$B$1000,"<>") -> 0 | C24: =COUNTIFS(Responses!$K$2:$K$1000,$A$6,Responses!$B$2:$B$1000,"<>") -> 0 | D24: =COUNTIFS(Responses!$K$2:$K$1000,$A$7,Responses!$B$2:$B$1000,"<>") -> 0 | E24: =COUNTIFS(Responses!$K$2:$K$1000,$A$8,Responses!$B$2:$B$1000,"<>") -> 0 | F24: =COUNTA(Responses!$B$2:$B$1000) -> 0
A25: 18 to 24 | B25: =COUNTIFS(Responses!$B$2:$B$1000,$A25,Responses!$K$2:$K$1000,$A$5) -> 0 | C25: =COUNTIFS(Responses!$B$2:$B$1000,$A25,Responses!$K$2:$K$1000,$A$6) -> 0 | D25: =COUNTIFS(Responses!$B$2:$B$1000,$A25,Responses!$K$2:$K$1000,$A$7) -> 0 | E25: =COUNTIFS(Responses!$B$2:$B$1000,$A25,Responses!$K$2:$K$1000,$A$8) -> 0 | F25: =COUNTIF(Responses!$B$2:$B$1000,$A25) -> 0 | H25: =IF(B$24=0,"",B25/B$24) | I25: =IF(C$24=0,"",C25/C$24) | J25: =IF(D$24=0,"",D25/D$24) | K25: =IF(E$24=0,"",E25/E$24) | L25: =IF(F$24=0,"",F25/F$24) | M25: =IF(COUNT(H25:K25)<2,"",MAX(H25:K25)-MIN(H25:K25)) | N25: Q1 | O25: =IF(M25="","",M25+ROW()/1000000000) | P25: =IF(M25="","",INDEX($A$5:$A$8,MATCH(MAX(H25:K25),H25:K25,0))) | Q25: =IF(M25="","",INDEX($A$5:$A$8,MATCH(MIN(H25:K25),H25:K25,0)))
A26: 25 to 34 | B26: =COUNTIFS(Responses!$B$2:$B$1000,$A26,Responses!$K$2:$K$1000,$A$5) -> 0 | C26: =COUNTIFS(Responses!$B$2:$B$1000,$A26,Responses!$K$2:$K$1000,$A$6) -> 0 | D26: =COUNTIFS(Responses!$B$2:$B$1000,$A26,Responses!$K$2:$K$1000,$A$7) -> 0 | E26: =COUNTIFS(Responses!$B$2:$B$1000,$A26,Responses!$K$2:$K$1000,$A$8) -> 0 | F26: =COUNTIF(Responses!$B$2:$B$1000,$A26) -> 0 | H26: =IF(B$24=0,"",B26/B$24) | I26: =IF(C$24=0,"",C26/C$24) | J26: =IF(D$24=0,"",D26/D$24) | K26: =IF(E$24=0,"",E26/E$24) | L26: =IF(F$24=0,"",F26/F$24) | M26: =IF(COUNT(H26:K26)<2,"",MAX(H26:K26)-MIN(H26:K26)) | N26: Q1 | O26: =IF(M26="","",M26+ROW()/1000000000) | P26: =IF(M26="","",INDEX($A$5:$A$8,MATCH(MAX(H26:K26),H26:K26,0))) | Q26: =IF(M26="","",INDEX($A$5:$A$8,MATCH(MIN(H26:K26),H26:K26,0)))
A27: 35 to 44 | B27: =COUNTIFS(Responses!$B$2:$B$1000,$A27,Responses!$K$2:$K$1000,$A$5) -> 0 | C27: =COUNTIFS(Responses!$B$2:$B$1000,$A27,Responses!$K$2:$K$1000,$A$6) -> 0 | D27: =COUNTIFS(Responses!$B$2:$B$1000,$A27,Responses!$K$2:$K$1000,$A$7) -> 0 | E27: =COUNTIFS(Responses!$B$2:$B$1000,$A27,Responses!$K$2:$K$1000,$A$8) -> 0 | F27: =COUNTIF(Responses!$B$2:$B$1000,$A27) -> 0 | H27: =IF(B$24=0,"",B27/B$24) | I27: =IF(C$24=0,"",C27/C$24) | J27: =IF(D$24=0,"",D27/D$24) | K27: =IF(E$24=0,"",E27/E$24) | L27: =IF(F$24=0,"",F27/F$24) | M27: =IF(COUNT(H27:K27)<2,"",MAX(H27:K27)-MIN(H27:K27)) | N27: Q1 | O27: =IF(M27="","",M27+ROW()/1000000000) | P27: =IF(M27="","",INDEX($A$5:$A$8,MATCH(MAX(H27:K27),H27:K27,0))) | Q27: =IF(M27="","",INDEX($A$5:$A$8,MATCH(MIN(H27:K27),H27:K27,0)))
A28: 45 or older | B28: =COUNTIFS(Responses!$B$2:$B$1000,$A28,Responses!$K$2:$K$1000,$A$5) -> 0 | C28: =COUNTIFS(Responses!$B$2:$B$1000,$A28,Responses!$K$2:$K$1000,$A$6) -> 0 | D28: =COUNTIFS(Responses!$B$2:$B$1000,$A28,Responses!$K$2:$K$1000,$A$7) -> 0 | E28: =COUNTIFS(Responses!$B$2:$B$1000,$A28,Responses!$K$2:$K$1000,$A$8) -> 0 | F28: =COUNTIF(Responses!$B$2:$B$1000,$A28) -> 0 | H28: =IF(B$24=0,"",B28/B$24) | I28: =IF(C$24=0,"",C28/C$24) | J28: =IF(D$24=0,"",D28/D$24) | K28: =IF(E$24=0,"",E28/E$24) | L28: =IF(F$24=0,"",F28/F$24) | M28: =IF(COUNT(H28:K28)<2,"",MAX(H28:K28)-MIN(H28:K28)) | N28: Q1 | O28: =IF(M28="","",M28+ROW()/1000000000) | P28: =IF(M28="","",INDEX($A$5:$A$8,MATCH(MAX(H28:K28),H28:K28,0))) | Q28: =IF(M28="","",INDEX($A$5:$A$8,MATCH(MIN(H28:K28),H28:K28,0)))
A31: Q2. Which best describes what you do right now?
A32: Base = respondents in the group who answered the question | B32: Count | H32: Column % (within group) | M32: Gap (max - min)
B33: =$A$5 -> Formal training | C33: =$A$6 -> Written policy or guidelines only | D33: =$A$7 -> Informal advice only | E33: =$A$8 -> No guidance at all | F33: All | H33: =$A$5 -> Formal training | I33: =$A$6 -> Written policy or guidelines only | J33: =$A$7 -> Informal advice only | K33: =$A$8 -> No guidance at all | L33: All
A34: Base (n answering) | B34: =COUNTIFS(Responses!$K$2:$K$1000,$A$5,Responses!$C$2:$C$1000,"<>") -> 0 | C34: =COUNTIFS(Responses!$K$2:$K$1000,$A$6,Responses!$C$2:$C$1000,"<>") -> 0 | D34: =COUNTIFS(Responses!$K$2:$K$1000,$A$7,Responses!$C$2:$C$1000,"<>") -> 0 | E34: =COUNTIFS(Responses!$K$2:$K$1000,$A$8,Responses!$C$2:$C$1000,"<>") -> 0 | F34: =COUNTA(Responses!$C$2:$C$1000) -> 0
A35: Student only | B35: =COUNTIFS(Responses!$C$2:$C$1000,$A35,Responses!$K$2:$K$1000,$A$5) -> 0 | C35: =COUNTIFS(Responses!$C$2:$C$1000,$A35,Responses!$K$2:$K$1000,$A$6) -> 0 | D35: =COUNTIFS(Responses!$C$2:$C$1000,$A35,Responses!$K$2:$K$1000,$A$7) -> 0 | E35: =COUNTIFS(Responses!$C$2:$C$1000,$A35,Responses!$K$2:$K$1000,$A$8) -> 0 | F35: =COUNTIF(Responses!$C$2:$C$1000,$A35) -> 0 | H35: =IF(B$34=0,"",B35/B$34) | I35: =IF(C$34=0,"",C35/C$34) | J35: =IF(D$34=0,"",D35/D$34) | K35: =IF(E$34=0,"",E35/E$34) | L35: =IF(F$34=0,"",F35/F$34) | M35: =IF(COUNT(H35:K35)<2,"",MAX(H35:K35)-MIN(H35:K35)) | N35: Q2 | O35: =IF(M35="","",M35+ROW()/1000000000) | P35: =IF(M35="","",INDEX($A$5:$A$8,MATCH(MAX(H35:K35),H35:K35,0))) | Q35: =IF(M35="","",INDEX($A$5:$A$8,MATCH(MIN(H35:K35),H35:K35,0)))
A36: Employed only (full-time or part-time) | B36: =COUNTIFS(Responses!$C$2:$C$1000,$A36,Responses!$K$2:$K$1000,$A$5) -> 0 | C36: =COUNTIFS(Responses!$C$2:$C$1000,$A36,Responses!$K$2:$K$1000,$A$6) -> 0 | D36: =COUNTIFS(Responses!$C$2:$C$1000,$A36,Responses!$K$2:$K$1000,$A$7) -> 0 | E36: =COUNTIFS(Responses!$C$2:$C$1000,$A36,Responses!$K$2:$K$1000,$A$8) -> 0 | F36: =COUNTIF(Responses!$C$2:$C$1000,$A36) -> 0 | H36: =IF(B$34=0,"",B36/B$34) | I36: =IF(C$34=0,"",C36/C$34) | J36: =IF(D$34=0,"",D36/D$34) | K36: =IF(E$34=0,"",E36/E$34) | L36: =IF(F$34=0,"",F36/F$34) | M36: =IF(COUNT(H36:K36)<2,"",MAX(H36:K36)-MIN(H36:K36)) | N36: Q2 | O36: =IF(M36="","",M36+ROW()/1000000000) | P36: =IF(M36="","",INDEX($A$5:$A$8,MATCH(MAX(H36:K36),H36:K36,0))) | Q36: =IF(M36="","",INDEX($A$5:$A$8,MATCH(MIN(H36:K36),H36:K36,0)))
A37: Both student and employed | B37: =COUNTIFS(Responses!$C$2:$C$1000,$A37,Responses!$K$2:$K$1000,$A$5) -> 0 | C37: =COUNTIFS(Responses!$C$2:$C$1000,$A37,Responses!$K$2:$K$1000,$A$6) -> 0 | D37: =COUNTIFS(Responses!$C$2:$C$1000,$A37,Responses!$K$2:$K$1000,$A$7) -> 0 | E37: =COUNTIFS(Responses!$C$2:$C$1000,$A37,Responses!$K$2:$K$1000,$A$8) -> 0 | F37: =COUNTIF(Responses!$C$2:$C$1000,$A37) -> 0 | H37: =IF(B$34=0,"",B37/B$34) | I37: =IF(C$34=0,"",C37/C$34) | J37: =IF(D$34=0,"",D37/D$34) | K37: =IF(E$34=0,"",E37/E$34) | L37: =IF(F$34=0,"",F37/F$34) | M37: =IF(COUNT(H37:K37)<2,"",MAX(H37:K37)-MIN(H37:K37)) | N37: Q2 | O37: =IF(M37="","",M37+ROW()/1000000000) | P37: =IF(M37="","",INDEX($A$5:$A$8,MATCH(MAX(H37:K37),H37:K37,0))) | Q37: =IF(M37="","",INDEX($A$5:$A$8,MATCH(MIN(H37:K37),H37:K37,0)))
A38: Neither at the moment | B38: =COUNTIFS(Responses!$C$2:$C$1000,$A38,Responses!$K$2:$K$1000,$A$5) -> 0 | C38: =COUNTIFS(Responses!$C$2:$C$1000,$A38,Responses!$K$2:$K$1000,$A$6) -> 0 | D38: =COUNTIFS(Responses!$C$2:$C$1000,$A38,Responses!$K$2:$K$1000,$A$7) -> 0 | E38: =COUNTIFS(Responses!$C$2:$C$1000,$A38,Responses!$K$2:$K$1000,$A$8) -> 0 | F38: =COUNTIF(Responses!$C$2:$C$1000,$A38) -> 0 | H38: =IF(B$34=0,"",B38/B$34) | I38: =IF(C$34=0,"",C38/C$34) | J38: =IF(D$34=0,"",D38/D$34) | K38: =IF(E$34=0,"",E38/E$34) | L38: =IF(F$34=0,"",F38/F$34) | M38: =IF(COUNT(H38:K38)<2,"",MAX(H38:K38)-MIN(H38:K38)) | N38: Q2 | O38: =IF(M38="","",M38+ROW()/1000000000) | P38: =IF(M38="","",INDEX($A$5:$A$8,MATCH(MAX(H38:K38),H38:K38,0))) | Q38: =IF(M38="","",INDEX($A$5:$A$8,MATCH(MIN(H38:K38),H38:K38,0)))
A41: Q3. How often do you use generative AI tools (for example ChatGPT, Copilot, Gemini or Claude) for work or study?
A42: Base = respondents in the group who answered the question | B42: Count | H42: Column % (within group) | M42: Gap (max - min)
B43: =$A$5 -> Formal training | C43: =$A$6 -> Written policy or guidelines only | D43: =$A$7 -> Informal advice only | E43: =$A$8 -> No guidance at all | F43: All | H43: =$A$5 -> Formal training | I43: =$A$6 -> Written policy or guidelines only | J43: =$A$7 -> Informal advice only | K43: =$A$8 -> No guidance at all | L43: All
A44: Base (n answering) | B44: =COUNTIFS(Responses!$K$2:$K$1000,$A$5,Responses!$D$2:$D$1000,"<>") -> 0 | C44: =COUNTIFS(Responses!$K$2:$K$1000,$A$6,Responses!$D$2:$D$1000,"<>") -> 0 | D44: =COUNTIFS(Responses!$K$2:$K$1000,$A$7,Responses!$D$2:$D$1000,"<>") -> 0 | E44: =COUNTIFS(Responses!$K$2:$K$1000,$A$8,Responses!$D$2:$D$1000,"<>") -> 0 | F44: =COUNTA(Responses!$D$2:$D$1000) -> 0
A45: Never | B45: =COUNTIFS(Responses!$D$2:$D$1000,$A45,Responses!$K$2:$K$1000,$A$5) -> 0 | C45: =COUNTIFS(Responses!$D$2:$D$1000,$A45,Responses!$K$2:$K$1000,$A$6) -> 0 | D45: =COUNTIFS(Responses!$D$2:$D$1000,$A45,Responses!$K$2:$K$1000,$A$7) -> 0 | E45: =COUNTIFS(Responses!$D$2:$D$1000,$A45,Responses!$K$2:$K$1000,$A$8) -> 0 | F45: =COUNTIF(Responses!$D$2:$D$1000,$A45) -> 0 | H45: =IF(B$44=0,"",B45/B$44) | I45: =IF(C$44=0,"",C45/C$44) | J45: =IF(D$44=0,"",D45/D$44) | K45: =IF(E$44=0,"",E45/E$44) | L45: =IF(F$44=0,"",F45/F$44) | M45: =IF(COUNT(H45:K45)<2,"",MAX(H45:K45)-MIN(H45:K45)) | N45: Q3 | O45: =IF(M45="","",M45+ROW()/1000000000) | P45: =IF(M45="","",INDEX($A$5:$A$8,MATCH(MAX(H45:K45),H45:K45,0))) | Q45: =IF(M45="","",INDEX($A$5:$A$8,MATCH(MIN(H45:K45),H45:K45,0)))
A46: Less than once a month | B46: =COUNTIFS(Responses!$D$2:$D$1000,$A46,Responses!$K$2:$K$1000,$A$5) -> 0 | C46: =COUNTIFS(Responses!$D$2:$D$1000,$A46,Responses!$K$2:$K$1000,$A$6) -> 0 | D46: =COUNTIFS(Responses!$D$2:$D$1000,$A46,Responses!$K$2:$K$1000,$A$7) -> 0 | E46: =COUNTIFS(Responses!$D$2:$D$1000,$A46,Responses!$K$2:$K$1000,$A$8) -> 0 | F46: =COUNTIF(Responses!$D$2:$D$1000,$A46) -> 0 | H46: =IF(B$44=0,"",B46/B$44) | I46: =IF(C$44=0,"",C46/C$44) | J46: =IF(D$44=0,"",D46/D$44) | K46: =IF(E$44=0,"",E46/E$44) | L46: =IF(F$44=0,"",F46/F$44) | M46: =IF(COUNT(H46:K46)<2,"",MAX(H46:K46)-MIN(H46:K46)) | N46: Q3 | O46: =IF(M46="","",M46+ROW()/1000000000) | P46: =IF(M46="","",INDEX($A$5:$A$8,MATCH(MAX(H46:K46),H46:K46,0))) | Q46: =IF(M46="","",INDEX($A$5:$A$8,MATCH(MIN(H46:K46),H46:K46,0)))
A47: A few times a month | B47: =COUNTIFS(Responses!$D$2:$D$1000,$A47,Responses!$K$2:$K$1000,$A$5) -> 0 | C47: =COUNTIFS(Responses!$D$2:$D$1000,$A47,Responses!$K$2:$K$1000,$A$6) -> 0 | D47: =COUNTIFS(Responses!$D$2:$D$1000,$A47,Responses!$K$2:$K$1000,$A$7) -> 0 | E47: =COUNTIFS(Responses!$D$2:$D$1000,$A47,Responses!$K$2:$K$1000,$A$8) -> 0 | F47: =COUNTIF(Responses!$D$2:$D$1000,$A47) -> 0 | H47: =IF(B$44=0,"",B47/B$44) | I47: =IF(C$44=0,"",C47/C$44) | J47: =IF(D$44=0,"",D47/D$44) | K47: =IF(E$44=0,"",E47/E$44) | L47: =IF(F$44=0,"",F47/F$44) | M47: =IF(COUNT(H47:K47)<2,"",MAX(H47:K47)-MIN(H47:K47)) | N47: Q3 | O47: =IF(M47="","",M47+ROW()/1000000000) | P47: =IF(M47="","",INDEX($A$5:$A$8,MATCH(MAX(H47:K47),H47:K47,0))) | Q47: =IF(M47="","",INDEX($A$5:$A$8,MATCH(MIN(H47:K47),H47:K47,0)))
A48: A few times a week | B48: =COUNTIFS(Responses!$D$2:$D$1000,$A48,Responses!$K$2:$K$1000,$A$5) -> 0 | C48: =COUNTIFS(Responses!$D$2:$D$1000,$A48,Responses!$K$2:$K$1000,$A$6) -> 0 | D48: =COUNTIFS(Responses!$D$2:$D$1000,$A48,Responses!$K$2:$K$1000,$A$7) -> 0 | E48: =COUNTIFS(Responses!$D$2:$D$1000,$A48,Responses!$K$2:$K$1000,$A$8) -> 0 | F48: =COUNTIF(Responses!$D$2:$D$1000,$A48) -> 0 | H48: =IF(B$44=0,"",B48/B$44) | I48: =IF(C$44=0,"",C48/C$44) | J48: =IF(D$44=0,"",D48/D$44) | K48: =IF(E$44=0,"",E48/E$44) | L48: =IF(F$44=0,"",F48/F$44) | M48: =IF(COUNT(H48:K48)<2,"",MAX(H48:K48)-MIN(H48:K48)) | N48: Q3 | O48: =IF(M48="","",M48+ROW()/1000000000) | P48: =IF(M48="","",INDEX($A$5:$A$8,MATCH(MAX(H48:K48),H48:K48,0))) | Q48: =IF(M48="","",INDEX($A$5:$A$8,MATCH(MIN(H48:K48),H48:K48,0)))
...

Sheet Codebook
A1: Q | B1: Column | C1: Header text on the form | D1: Type | E1: Answer options | F1: Shown to | G1: Why we ask it
A2: Q1 | B2: B | C2: Q1. Which age group are you in? | D2: Multiple choice (single answer) | E2: 18 to 24; 25 to 34; 35 to 44; 45 or older | F2: All respondents | G2: Primary demographic lens: lets us test whether adoption and attitudes differ by generation.
A3: Q2 | B3: C | C3: Q2. Which best describes what you do right now? | D3: Multiple choice (single answer) | E3: Student only; Employed only (full-time or part-time); Both student and employed; Neither at the moment | F3: All respondents | G3: Second lens: separates workplace experience from classroom experience.
A4: Q3 | B4: D | C4: Q3. How often do you use generative AI tools (for example ChatGPT, Copilot, Gemini or Claude) for work or study? | D4: Multiple choice (single answer) | E4: Never; Less than once a month; A few times a month; A few times a week; Daily | F4: All respondents | G4: Core adoption measure. Ordered scale makes group comparisons easy. 'Never' branches non-users past questions that do not apply to them.
A5: Q4 | B5: E | C5: Q4. Which tasks do you use AI tools for? Select all that apply. | D5: Checkboxes (select all / up to N) | E5: Writing or editing; Research or summarizing; Brainstorming ideas; Analyzing data or spreadsheets; Coding or technical help; Translation or language support; Scheduling or admin tasks | F5: AI users (Q3 not 'Never') | G5: Shows where AI is actually used, which tells an organization where training and tools would matter most.
A6: Q5 | B6: F | C6: Q5. On average, about how much time per week do AI tools save you? | D6: Multiple choice (single answer) | E6: None - no time saved; Less than 1 hour; 1 to 3 hours; 4 to 6 hours; 7 or more hours | F6: AI users (Q3 not 'Never') | G6: A concrete, business-relevant productivity measure (hours) rather than a vague opinion.
A7: Q6 | B7: G | C7: Q6. How much do you agree with each statement about your own use of AI tools? [AI tools help me complete tasks faster.] | D7: Likert grid (5-point agreement) | E7: Strongly disagree; Disagree; Neutral; Agree; Strongly agree | F7: AI users (Q3 not 'Never') | G7: Likert grid: efficient way to capture speed, quality and verification behaviour (a trust/risk proxy) in one question.
A8: Q6 | B8: H | C8: Q6. How much do you agree with each statement about your own use of AI tools? [AI tools improve the quality of my work.] | D8: Likert grid (5-point agreement) | E8: Strongly disagree; Disagree; Neutral; Agree; Strongly agree | F8: AI users (Q3 not 'Never')
A9: Q6 | B9: I | C9: Q6. How much do you agree with each statement about your own use of AI tools? [I always check AI-generated output before I use it.] | D9: Likert grid (5-point agreement) | E9: Strongly disagree; Disagree; Neutral; Agree; Strongly agree | F9: AI users (Q3 not 'Never')
A10: Q7 | B10: J | C10: Q7. How confident are you in your ability to use AI tools effectively? | D10: Linear scale (1 to 5) | E10: 1 (Not at all confident) to 5 (Very confident) | F10: AI users (Q3 not 'Never') | G10: Self-rated skill. Cross-tabbed against training received (Q8) to test whether support builds confidence.
A11: Q8 | B11: K | C11: Q8. Which best describes the guidance you have received about using AI tools from your employer or school? | D11: Multiple choice (single answer) | E11: Formal training; Written policy or guidelines only; Informal advice only; No guidance at all | F11: All respondents | G11: Measures the support gap. Used as a third analysis lens against confidence and barriers.
A12: Q9 | B12: L | C12: Q9. Which best describes your employer's or school's current approach to AI tools? | D12: Multiple choice (single answer) | E12: Encouraged and supported; Allowed with rules; Discouraged or restricted; Banned; Not sure or no policy | F12: All respondents | G12: Captures the policy environment people work in, including how many do not know the policy.
A13: Q10 | B13: M | C13: Q10. What are the biggest barriers to using AI tools (more) in your work or study? Select up to 3. | D13: Checkboxes (select all / up to N) | E13: Concerns about accuracy; Data privacy or confidentiality concerns; Rules or policy restrictions; Lack of training or skills; Cost of tools; Academic or professional integrity concerns; I do not see a need | F13: All respondents | G13: Limited to 3 choices to force prioritization. Answered by users and non-users alike.
A14: Q11 | B14: N | C14: Q11. "AI will reduce job opportunities in my field over the next 5 years." How much do you agree? | D14: Linear scale (1 to 5) | E14: 1 (Strongly disagree) to 5 (Strongly agree) | F14: All respondents | G14: Gauges workforce anxiety, a change-management risk for any organization adopting AI.
A15: Q12 | B15: O | C15: Q12. If your employer or school invested in ONE of these, which would help you most? | D15: Multiple choice (single answer) | E15: Approved and secure AI tools; Training workshops; Clear policy and guidelines; Time to experiment with tools; None of these - no investment needed | F15: All respondents | G15: Directly supports the recommendation: where should an organization spend first?
